{
 "cells": [
  {
   "cell_type": "code",
   "execution_count": 2,
   "metadata": {},
   "outputs": [],
   "source": [
    "!pip install -q transformers accelerate sentencepiece\n"
   ]
  },
  {
   "cell_type": "code",
   "execution_count": 3,
   "metadata": {},
   "outputs": [
    {
     "name": "stderr",
     "output_type": "stream",
     "text": [
      "'huggingface-cil'��(��) ���� �Ǵ� �ܺ� ����, ������ �� �ִ� ���α׷�, �Ǵ�\n",
      "��ġ ������ �ƴմϴ�.\n"
     ]
    }
   ],
   "source": [
    "!huggingface-cil login"
   ]
  },
  {
   "cell_type": "code",
   "execution_count": 8,
   "metadata": {},
   "outputs": [
    {
     "name": "stdout",
     "output_type": "stream",
     "text": [
      "Requirement already satisfied: transformers in c:\\users\\hyun9\\anaconda3\\envs\\py3.8\\lib\\site-packages (4.31.0)\n",
      "Requirement already satisfied: numpy>=1.17 in c:\\users\\hyun9\\anaconda3\\envs\\py3.8\\lib\\site-packages (from transformers) (1.23.5)\n",
      "Requirement already satisfied: regex!=2019.12.17 in c:\\users\\hyun9\\anaconda3\\envs\\py3.8\\lib\\site-packages (from transformers) (2023.6.3)\n",
      "Requirement already satisfied: safetensors>=0.3.1 in c:\\users\\hyun9\\anaconda3\\envs\\py3.8\\lib\\site-packages (from transformers) (0.3.2)\n",
      "Requirement already satisfied: requests in c:\\users\\hyun9\\anaconda3\\envs\\py3.8\\lib\\site-packages (from transformers) (2.31.0)\n",
      "Requirement already satisfied: filelock in c:\\users\\hyun9\\anaconda3\\envs\\py3.8\\lib\\site-packages (from transformers) (3.12.2)\n",
      "Requirement already satisfied: packaging>=20.0 in c:\\users\\hyun9\\anaconda3\\envs\\py3.8\\lib\\site-packages (from transformers) (23.1)\n",
      "Requirement already satisfied: pyyaml>=5.1 in c:\\users\\hyun9\\anaconda3\\envs\\py3.8\\lib\\site-packages (from transformers) (6.0.1)\n",
      "Requirement already satisfied: huggingface-hub<1.0,>=0.14.1 in c:\\users\\hyun9\\anaconda3\\envs\\py3.8\\lib\\site-packages (from transformers) (0.16.4)\n",
      "Requirement already satisfied: tqdm>=4.27 in c:\\users\\hyun9\\anaconda3\\envs\\py3.8\\lib\\site-packages (from transformers) (4.65.0)\n",
      "Requirement already satisfied: tokenizers!=0.11.3,<0.14,>=0.11.1 in c:\\users\\hyun9\\anaconda3\\envs\\py3.8\\lib\\site-packages (from transformers) (0.13.3)\n",
      "Requirement already satisfied: typing-extensions>=3.7.4.3 in c:\\users\\hyun9\\anaconda3\\envs\\py3.8\\lib\\site-packages (from huggingface-hub<1.0,>=0.14.1->transformers) (4.6.3)\n",
      "Requirement already satisfied: fsspec in c:\\users\\hyun9\\anaconda3\\envs\\py3.8\\lib\\site-packages (from huggingface-hub<1.0,>=0.14.1->transformers) (2023.6.0)\n",
      "Requirement already satisfied: colorama in c:\\users\\hyun9\\anaconda3\\envs\\py3.8\\lib\\site-packages (from tqdm>=4.27->transformers) (0.4.6)\n",
      "Requirement already satisfied: certifi>=2017.4.17 in c:\\users\\hyun9\\anaconda3\\envs\\py3.8\\lib\\site-packages (from requests->transformers) (2023.5.7)\n",
      "Requirement already satisfied: urllib3<3,>=1.21.1 in c:\\users\\hyun9\\anaconda3\\envs\\py3.8\\lib\\site-packages (from requests->transformers) (1.26.16)\n",
      "Requirement already satisfied: idna<4,>=2.5 in c:\\users\\hyun9\\anaconda3\\envs\\py3.8\\lib\\site-packages (from requests->transformers) (3.4)\n",
      "Requirement already satisfied: charset-normalizer<4,>=2 in c:\\users\\hyun9\\anaconda3\\envs\\py3.8\\lib\\site-packages (from requests->transformers) (3.1.0)\n",
      "Note: you may need to restart the kernel to use updated packages.\n"
     ]
    }
   ],
   "source": [
    "pip install transformers"
   ]
  },
  {
   "cell_type": "code",
   "execution_count": 5,
   "metadata": {},
   "outputs": [
    {
     "ename": "OSError",
     "evalue": "meta-llama/Llama-2-70b-chat-hf is not a local folder and is not a valid model identifier listed on 'https://huggingface.co/models'\nIf this is a private repository, make sure to pass a token having permission to this repo with `use_auth_token` or log in with `huggingface-cli login` and pass `use_auth_token=True`.",
     "output_type": "error",
     "traceback": [
      "\u001b[1;31m---------------------------------------------------------------------------\u001b[0m",
      "\u001b[1;31mHTTPError\u001b[0m                                 Traceback (most recent call last)",
      "File \u001b[1;32mc:\\Users\\hyun9\\anaconda3\\envs\\py3.8\\lib\\site-packages\\huggingface_hub\\utils\\_errors.py:261\u001b[0m, in \u001b[0;36mhf_raise_for_status\u001b[1;34m(response, endpoint_name)\u001b[0m\n\u001b[0;32m    260\u001b[0m \u001b[39mtry\u001b[39;00m:\n\u001b[1;32m--> 261\u001b[0m     response\u001b[39m.\u001b[39;49mraise_for_status()\n\u001b[0;32m    262\u001b[0m \u001b[39mexcept\u001b[39;00m HTTPError \u001b[39mas\u001b[39;00m e:\n",
      "File \u001b[1;32mc:\\Users\\hyun9\\anaconda3\\envs\\py3.8\\lib\\site-packages\\requests\\models.py:1021\u001b[0m, in \u001b[0;36mResponse.raise_for_status\u001b[1;34m(self)\u001b[0m\n\u001b[0;32m   1020\u001b[0m \u001b[39mif\u001b[39;00m http_error_msg:\n\u001b[1;32m-> 1021\u001b[0m     \u001b[39mraise\u001b[39;00m HTTPError(http_error_msg, response\u001b[39m=\u001b[39m\u001b[39mself\u001b[39m)\n",
      "\u001b[1;31mHTTPError\u001b[0m: 401 Client Error: Unauthorized for url: https://huggingface.co/meta-llama/Llama-2-70b-chat-hf/resolve/main/tokenizer_config.json",
      "\nThe above exception was the direct cause of the following exception:\n",
      "\u001b[1;31mGatedRepoError\u001b[0m                            Traceback (most recent call last)",
      "File \u001b[1;32mc:\\Users\\hyun9\\anaconda3\\envs\\py3.8\\lib\\site-packages\\transformers\\utils\\hub.py:417\u001b[0m, in \u001b[0;36mcached_file\u001b[1;34m(path_or_repo_id, filename, cache_dir, force_download, resume_download, proxies, use_auth_token, revision, local_files_only, subfolder, repo_type, user_agent, _raise_exceptions_for_missing_entries, _raise_exceptions_for_connection_errors, _commit_hash)\u001b[0m\n\u001b[0;32m    415\u001b[0m \u001b[39mtry\u001b[39;00m:\n\u001b[0;32m    416\u001b[0m     \u001b[39m# Load from URL or cache if already cached\u001b[39;00m\n\u001b[1;32m--> 417\u001b[0m     resolved_file \u001b[39m=\u001b[39m hf_hub_download(\n\u001b[0;32m    418\u001b[0m         path_or_repo_id,\n\u001b[0;32m    419\u001b[0m         filename,\n\u001b[0;32m    420\u001b[0m         subfolder\u001b[39m=\u001b[39;49m\u001b[39mNone\u001b[39;49;00m \u001b[39mif\u001b[39;49;00m \u001b[39mlen\u001b[39;49m(subfolder) \u001b[39m==\u001b[39;49m \u001b[39m0\u001b[39;49m \u001b[39melse\u001b[39;49;00m subfolder,\n\u001b[0;32m    421\u001b[0m         repo_type\u001b[39m=\u001b[39;49mrepo_type,\n\u001b[0;32m    422\u001b[0m         revision\u001b[39m=\u001b[39;49mrevision,\n\u001b[0;32m    423\u001b[0m         cache_dir\u001b[39m=\u001b[39;49mcache_dir,\n\u001b[0;32m    424\u001b[0m         user_agent\u001b[39m=\u001b[39;49muser_agent,\n\u001b[0;32m    425\u001b[0m         force_download\u001b[39m=\u001b[39;49mforce_download,\n\u001b[0;32m    426\u001b[0m         proxies\u001b[39m=\u001b[39;49mproxies,\n\u001b[0;32m    427\u001b[0m         resume_download\u001b[39m=\u001b[39;49mresume_download,\n\u001b[0;32m    428\u001b[0m         use_auth_token\u001b[39m=\u001b[39;49muse_auth_token,\n\u001b[0;32m    429\u001b[0m         local_files_only\u001b[39m=\u001b[39;49mlocal_files_only,\n\u001b[0;32m    430\u001b[0m     )\n\u001b[0;32m    432\u001b[0m \u001b[39mexcept\u001b[39;00m RepositoryNotFoundError:\n",
      "File \u001b[1;32mc:\\Users\\hyun9\\anaconda3\\envs\\py3.8\\lib\\site-packages\\huggingface_hub\\utils\\_validators.py:118\u001b[0m, in \u001b[0;36mvalidate_hf_hub_args.<locals>._inner_fn\u001b[1;34m(*args, **kwargs)\u001b[0m\n\u001b[0;32m    116\u001b[0m     kwargs \u001b[39m=\u001b[39m smoothly_deprecate_use_auth_token(fn_name\u001b[39m=\u001b[39mfn\u001b[39m.\u001b[39m\u001b[39m__name__\u001b[39m, has_token\u001b[39m=\u001b[39mhas_token, kwargs\u001b[39m=\u001b[39mkwargs)\n\u001b[1;32m--> 118\u001b[0m \u001b[39mreturn\u001b[39;00m fn(\u001b[39m*\u001b[39;49margs, \u001b[39m*\u001b[39;49m\u001b[39m*\u001b[39;49mkwargs)\n",
      "File \u001b[1;32mc:\\Users\\hyun9\\anaconda3\\envs\\py3.8\\lib\\site-packages\\huggingface_hub\\file_download.py:1195\u001b[0m, in \u001b[0;36mhf_hub_download\u001b[1;34m(repo_id, filename, subfolder, repo_type, revision, library_name, library_version, cache_dir, local_dir, local_dir_use_symlinks, user_agent, force_download, force_filename, proxies, etag_timeout, resume_download, token, local_files_only, legacy_cache_layout)\u001b[0m\n\u001b[0;32m   1194\u001b[0m \u001b[39mtry\u001b[39;00m:\n\u001b[1;32m-> 1195\u001b[0m     metadata \u001b[39m=\u001b[39m get_hf_file_metadata(\n\u001b[0;32m   1196\u001b[0m         url\u001b[39m=\u001b[39;49murl,\n\u001b[0;32m   1197\u001b[0m         token\u001b[39m=\u001b[39;49mtoken,\n\u001b[0;32m   1198\u001b[0m         proxies\u001b[39m=\u001b[39;49mproxies,\n\u001b[0;32m   1199\u001b[0m         timeout\u001b[39m=\u001b[39;49metag_timeout,\n\u001b[0;32m   1200\u001b[0m     )\n\u001b[0;32m   1201\u001b[0m \u001b[39mexcept\u001b[39;00m EntryNotFoundError \u001b[39mas\u001b[39;00m http_error:\n\u001b[0;32m   1202\u001b[0m     \u001b[39m# Cache the non-existence of the file and raise\u001b[39;00m\n",
      "File \u001b[1;32mc:\\Users\\hyun9\\anaconda3\\envs\\py3.8\\lib\\site-packages\\huggingface_hub\\utils\\_validators.py:118\u001b[0m, in \u001b[0;36mvalidate_hf_hub_args.<locals>._inner_fn\u001b[1;34m(*args, **kwargs)\u001b[0m\n\u001b[0;32m    116\u001b[0m     kwargs \u001b[39m=\u001b[39m smoothly_deprecate_use_auth_token(fn_name\u001b[39m=\u001b[39mfn\u001b[39m.\u001b[39m\u001b[39m__name__\u001b[39m, has_token\u001b[39m=\u001b[39mhas_token, kwargs\u001b[39m=\u001b[39mkwargs)\n\u001b[1;32m--> 118\u001b[0m \u001b[39mreturn\u001b[39;00m fn(\u001b[39m*\u001b[39;49margs, \u001b[39m*\u001b[39;49m\u001b[39m*\u001b[39;49mkwargs)\n",
      "File \u001b[1;32mc:\\Users\\hyun9\\anaconda3\\envs\\py3.8\\lib\\site-packages\\huggingface_hub\\file_download.py:1541\u001b[0m, in \u001b[0;36mget_hf_file_metadata\u001b[1;34m(url, token, proxies, timeout)\u001b[0m\n\u001b[0;32m   1532\u001b[0m r \u001b[39m=\u001b[39m _request_wrapper(\n\u001b[0;32m   1533\u001b[0m     method\u001b[39m=\u001b[39m\u001b[39m\"\u001b[39m\u001b[39mHEAD\u001b[39m\u001b[39m\"\u001b[39m,\n\u001b[0;32m   1534\u001b[0m     url\u001b[39m=\u001b[39murl,\n\u001b[1;32m   (...)\u001b[0m\n\u001b[0;32m   1539\u001b[0m     timeout\u001b[39m=\u001b[39mtimeout,\n\u001b[0;32m   1540\u001b[0m )\n\u001b[1;32m-> 1541\u001b[0m hf_raise_for_status(r)\n\u001b[0;32m   1543\u001b[0m \u001b[39m# Return\u001b[39;00m\n",
      "File \u001b[1;32mc:\\Users\\hyun9\\anaconda3\\envs\\py3.8\\lib\\site-packages\\huggingface_hub\\utils\\_errors.py:277\u001b[0m, in \u001b[0;36mhf_raise_for_status\u001b[1;34m(response, endpoint_name)\u001b[0m\n\u001b[0;32m    274\u001b[0m     message \u001b[39m=\u001b[39m (\n\u001b[0;32m    275\u001b[0m         \u001b[39mf\u001b[39m\u001b[39m\"\u001b[39m\u001b[39m{\u001b[39;00mresponse\u001b[39m.\u001b[39mstatus_code\u001b[39m}\u001b[39;00m\u001b[39m Client Error.\u001b[39m\u001b[39m\"\u001b[39m \u001b[39m+\u001b[39m \u001b[39m\"\u001b[39m\u001b[39m\\n\u001b[39;00m\u001b[39m\\n\u001b[39;00m\u001b[39m\"\u001b[39m \u001b[39m+\u001b[39m \u001b[39mf\u001b[39m\u001b[39m\"\u001b[39m\u001b[39mCannot access gated repo for url \u001b[39m\u001b[39m{\u001b[39;00mresponse\u001b[39m.\u001b[39murl\u001b[39m}\u001b[39;00m\u001b[39m.\u001b[39m\u001b[39m\"\u001b[39m\n\u001b[0;32m    276\u001b[0m     )\n\u001b[1;32m--> 277\u001b[0m     \u001b[39mraise\u001b[39;00m GatedRepoError(message, response) \u001b[39mfrom\u001b[39;00m \u001b[39me\u001b[39;00m\n\u001b[0;32m    279\u001b[0m \u001b[39melif\u001b[39;00m error_code \u001b[39m==\u001b[39m \u001b[39m\"\u001b[39m\u001b[39mRepoNotFound\u001b[39m\u001b[39m\"\u001b[39m \u001b[39mor\u001b[39;00m response\u001b[39m.\u001b[39mstatus_code \u001b[39m==\u001b[39m \u001b[39m401\u001b[39m:\n\u001b[0;32m    280\u001b[0m     \u001b[39m# 401 is misleading as it is returned for:\u001b[39;00m\n\u001b[0;32m    281\u001b[0m     \u001b[39m#    - private and gated repos if user is not authenticated\u001b[39;00m\n\u001b[0;32m    282\u001b[0m     \u001b[39m#    - missing repos\u001b[39;00m\n\u001b[0;32m    283\u001b[0m     \u001b[39m# => for now, we process them as `RepoNotFound` anyway.\u001b[39;00m\n\u001b[0;32m    284\u001b[0m     \u001b[39m# See https://gist.github.com/Wauplin/46c27ad266b15998ce56a6603796f0b9\u001b[39;00m\n",
      "\u001b[1;31mGatedRepoError\u001b[0m: 401 Client Error. (Request ID: Root=1-64dc8b57-06b20f8628696921371aa120;274d13a2-a575-4265-a82b-6448d5be9a72)\n\nCannot access gated repo for url https://huggingface.co/meta-llama/Llama-2-70b-chat-hf/resolve/main/tokenizer_config.json.\nRepo model meta-llama/Llama-2-70b-chat-hf is gated. You must be authenticated to access it.",
      "\nDuring handling of the above exception, another exception occurred:\n",
      "\u001b[1;31mOSError\u001b[0m                                   Traceback (most recent call last)",
      "Cell \u001b[1;32mIn[5], line 4\u001b[0m\n\u001b[0;32m      1\u001b[0m \u001b[39m# Load model directly\u001b[39;00m\n\u001b[0;32m      2\u001b[0m \u001b[39mfrom\u001b[39;00m \u001b[39mtransformers\u001b[39;00m \u001b[39mimport\u001b[39;00m AutoTokenizer, AutoModelForCausalLM\n\u001b[1;32m----> 4\u001b[0m tokenizer \u001b[39m=\u001b[39m AutoTokenizer\u001b[39m.\u001b[39;49mfrom_pretrained(\u001b[39m\"\u001b[39;49m\u001b[39mmeta-llama/Llama-2-70b-chat-hf\u001b[39;49m\u001b[39m\"\u001b[39;49m)\n\u001b[0;32m      5\u001b[0m model \u001b[39m=\u001b[39m AutoModelForCausalLM\u001b[39m.\u001b[39mfrom_pretrained(\u001b[39m\"\u001b[39m\u001b[39mmeta-llama/Llama-2-70b-chat-hf\u001b[39m\u001b[39m\"\u001b[39m)\n",
      "File \u001b[1;32mc:\\Users\\hyun9\\anaconda3\\envs\\py3.8\\lib\\site-packages\\transformers\\models\\auto\\tokenization_auto.py:652\u001b[0m, in \u001b[0;36mAutoTokenizer.from_pretrained\u001b[1;34m(cls, pretrained_model_name_or_path, *inputs, **kwargs)\u001b[0m\n\u001b[0;32m    649\u001b[0m     \u001b[39mreturn\u001b[39;00m tokenizer_class\u001b[39m.\u001b[39mfrom_pretrained(pretrained_model_name_or_path, \u001b[39m*\u001b[39minputs, \u001b[39m*\u001b[39m\u001b[39m*\u001b[39mkwargs)\n\u001b[0;32m    651\u001b[0m \u001b[39m# Next, let's try to use the tokenizer_config file to get the tokenizer class.\u001b[39;00m\n\u001b[1;32m--> 652\u001b[0m tokenizer_config \u001b[39m=\u001b[39m get_tokenizer_config(pretrained_model_name_or_path, \u001b[39m*\u001b[39;49m\u001b[39m*\u001b[39;49mkwargs)\n\u001b[0;32m    653\u001b[0m \u001b[39mif\u001b[39;00m \u001b[39m\"\u001b[39m\u001b[39m_commit_hash\u001b[39m\u001b[39m\"\u001b[39m \u001b[39min\u001b[39;00m tokenizer_config:\n\u001b[0;32m    654\u001b[0m     kwargs[\u001b[39m\"\u001b[39m\u001b[39m_commit_hash\u001b[39m\u001b[39m\"\u001b[39m] \u001b[39m=\u001b[39m tokenizer_config[\u001b[39m\"\u001b[39m\u001b[39m_commit_hash\u001b[39m\u001b[39m\"\u001b[39m]\n",
      "File \u001b[1;32mc:\\Users\\hyun9\\anaconda3\\envs\\py3.8\\lib\\site-packages\\transformers\\models\\auto\\tokenization_auto.py:496\u001b[0m, in \u001b[0;36mget_tokenizer_config\u001b[1;34m(pretrained_model_name_or_path, cache_dir, force_download, resume_download, proxies, use_auth_token, revision, local_files_only, subfolder, **kwargs)\u001b[0m\n\u001b[0;32m    434\u001b[0m \u001b[39m\u001b[39m\u001b[39m\"\"\"\u001b[39;00m\n\u001b[0;32m    435\u001b[0m \u001b[39mLoads the tokenizer configuration from a pretrained model tokenizer configuration.\u001b[39;00m\n\u001b[0;32m    436\u001b[0m \n\u001b[1;32m   (...)\u001b[0m\n\u001b[0;32m    493\u001b[0m \u001b[39mtokenizer_config = get_tokenizer_config(\"tokenizer-test\")\u001b[39;00m\n\u001b[0;32m    494\u001b[0m \u001b[39m```\"\"\"\u001b[39;00m\n\u001b[0;32m    495\u001b[0m commit_hash \u001b[39m=\u001b[39m kwargs\u001b[39m.\u001b[39mget(\u001b[39m\"\u001b[39m\u001b[39m_commit_hash\u001b[39m\u001b[39m\"\u001b[39m, \u001b[39mNone\u001b[39;00m)\n\u001b[1;32m--> 496\u001b[0m resolved_config_file \u001b[39m=\u001b[39m cached_file(\n\u001b[0;32m    497\u001b[0m     pretrained_model_name_or_path,\n\u001b[0;32m    498\u001b[0m     TOKENIZER_CONFIG_FILE,\n\u001b[0;32m    499\u001b[0m     cache_dir\u001b[39m=\u001b[39;49mcache_dir,\n\u001b[0;32m    500\u001b[0m     force_download\u001b[39m=\u001b[39;49mforce_download,\n\u001b[0;32m    501\u001b[0m     resume_download\u001b[39m=\u001b[39;49mresume_download,\n\u001b[0;32m    502\u001b[0m     proxies\u001b[39m=\u001b[39;49mproxies,\n\u001b[0;32m    503\u001b[0m     use_auth_token\u001b[39m=\u001b[39;49muse_auth_token,\n\u001b[0;32m    504\u001b[0m     revision\u001b[39m=\u001b[39;49mrevision,\n\u001b[0;32m    505\u001b[0m     local_files_only\u001b[39m=\u001b[39;49mlocal_files_only,\n\u001b[0;32m    506\u001b[0m     subfolder\u001b[39m=\u001b[39;49msubfolder,\n\u001b[0;32m    507\u001b[0m     _raise_exceptions_for_missing_entries\u001b[39m=\u001b[39;49m\u001b[39mFalse\u001b[39;49;00m,\n\u001b[0;32m    508\u001b[0m     _raise_exceptions_for_connection_errors\u001b[39m=\u001b[39;49m\u001b[39mFalse\u001b[39;49;00m,\n\u001b[0;32m    509\u001b[0m     _commit_hash\u001b[39m=\u001b[39;49mcommit_hash,\n\u001b[0;32m    510\u001b[0m )\n\u001b[0;32m    511\u001b[0m \u001b[39mif\u001b[39;00m resolved_config_file \u001b[39mis\u001b[39;00m \u001b[39mNone\u001b[39;00m:\n\u001b[0;32m    512\u001b[0m     logger\u001b[39m.\u001b[39minfo(\u001b[39m\"\u001b[39m\u001b[39mCould not locate the tokenizer configuration file, will try to use the model config instead.\u001b[39m\u001b[39m\"\u001b[39m)\n",
      "File \u001b[1;32mc:\\Users\\hyun9\\anaconda3\\envs\\py3.8\\lib\\site-packages\\transformers\\utils\\hub.py:433\u001b[0m, in \u001b[0;36mcached_file\u001b[1;34m(path_or_repo_id, filename, cache_dir, force_download, resume_download, proxies, use_auth_token, revision, local_files_only, subfolder, repo_type, user_agent, _raise_exceptions_for_missing_entries, _raise_exceptions_for_connection_errors, _commit_hash)\u001b[0m\n\u001b[0;32m    417\u001b[0m     resolved_file \u001b[39m=\u001b[39m hf_hub_download(\n\u001b[0;32m    418\u001b[0m         path_or_repo_id,\n\u001b[0;32m    419\u001b[0m         filename,\n\u001b[1;32m   (...)\u001b[0m\n\u001b[0;32m    429\u001b[0m         local_files_only\u001b[39m=\u001b[39mlocal_files_only,\n\u001b[0;32m    430\u001b[0m     )\n\u001b[0;32m    432\u001b[0m \u001b[39mexcept\u001b[39;00m RepositoryNotFoundError:\n\u001b[1;32m--> 433\u001b[0m     \u001b[39mraise\u001b[39;00m \u001b[39mEnvironmentError\u001b[39;00m(\n\u001b[0;32m    434\u001b[0m         \u001b[39mf\u001b[39m\u001b[39m\"\u001b[39m\u001b[39m{\u001b[39;00mpath_or_repo_id\u001b[39m}\u001b[39;00m\u001b[39m is not a local folder and is not a valid model identifier \u001b[39m\u001b[39m\"\u001b[39m\n\u001b[0;32m    435\u001b[0m         \u001b[39m\"\u001b[39m\u001b[39mlisted on \u001b[39m\u001b[39m'\u001b[39m\u001b[39mhttps://huggingface.co/models\u001b[39m\u001b[39m'\u001b[39m\u001b[39m\\n\u001b[39;00m\u001b[39mIf this is a private repository, make sure to \u001b[39m\u001b[39m\"\u001b[39m\n\u001b[0;32m    436\u001b[0m         \u001b[39m\"\u001b[39m\u001b[39mpass a token having permission to this repo with `use_auth_token` or log in with \u001b[39m\u001b[39m\"\u001b[39m\n\u001b[0;32m    437\u001b[0m         \u001b[39m\"\u001b[39m\u001b[39m`huggingface-cli login` and pass `use_auth_token=True`.\u001b[39m\u001b[39m\"\u001b[39m\n\u001b[0;32m    438\u001b[0m     )\n\u001b[0;32m    439\u001b[0m \u001b[39mexcept\u001b[39;00m RevisionNotFoundError:\n\u001b[0;32m    440\u001b[0m     \u001b[39mraise\u001b[39;00m \u001b[39mEnvironmentError\u001b[39;00m(\n\u001b[0;32m    441\u001b[0m         \u001b[39mf\u001b[39m\u001b[39m\"\u001b[39m\u001b[39m{\u001b[39;00mrevision\u001b[39m}\u001b[39;00m\u001b[39m is not a valid git identifier (branch name, tag name or commit id) that exists \u001b[39m\u001b[39m\"\u001b[39m\n\u001b[0;32m    442\u001b[0m         \u001b[39m\"\u001b[39m\u001b[39mfor this model name. Check the model page at \u001b[39m\u001b[39m\"\u001b[39m\n\u001b[0;32m    443\u001b[0m         \u001b[39mf\u001b[39m\u001b[39m\"\u001b[39m\u001b[39m'\u001b[39m\u001b[39mhttps://huggingface.co/\u001b[39m\u001b[39m{\u001b[39;00mpath_or_repo_id\u001b[39m}\u001b[39;00m\u001b[39m'\u001b[39m\u001b[39m for available revisions.\u001b[39m\u001b[39m\"\u001b[39m\n\u001b[0;32m    444\u001b[0m     )\n",
      "\u001b[1;31mOSError\u001b[0m: meta-llama/Llama-2-70b-chat-hf is not a local folder and is not a valid model identifier listed on 'https://huggingface.co/models'\nIf this is a private repository, make sure to pass a token having permission to this repo with `use_auth_token` or log in with `huggingface-cli login` and pass `use_auth_token=True`."
     ]
    }
   ],
   "source": [
    "# Load model directly\n",
    "from transformers import AutoTokenizer, AutoModelForCausalLM\n",
    "\n",
    "tokenizer = AutoTokenizer.from_pretrained(\"meta-llama/Llama-2-70b-chat-hf\")\n",
    "model = AutoModelForCausalLM.from_pretrained(\"meta-llama/Llama-2-70b-chat-hf\")"
   ]
  },
  {
   "cell_type": "code",
   "execution_count": null,
   "metadata": {},
   "outputs": [],
   "source": []
  }
 ],
 "metadata": {
  "kernelspec": {
   "display_name": "py3.8",
   "language": "python",
   "name": "python3"
  },
  "language_info": {
   "codemirror_mode": {
    "name": "ipython",
    "version": 3
   },
   "file_extension": ".py",
   "mimetype": "text/x-python",
   "name": "python",
   "nbconvert_exporter": "python",
   "pygments_lexer": "ipython3",
   "version": "3.8.16"
  },
  "orig_nbformat": 4
 },
 "nbformat": 4,
 "nbformat_minor": 2
}
